<?xml version="1.0" encoding="utf-8"?>
<!-- This URDF was automatically created by SolidWorks to URDF Exporter! Originally created by Stephen Brawner (brawner@gmail.com) 
     Commit Version: 1.6.0-4-g7f85cfe  Build Version: 1.6.7995.38578
     For more information, please see http://wiki.ros.org/sw_urdf_exporter -->
<robot
  name="matrix_true_description">
  <link
    name="base_link">
    <inertial>
      <origin
        xyz="-0.0193327740236747 0.000357362284587354 0.302224740304159"
        rpy="0 0 0" />
      <mass
        value="95.4830322905057" />
      <inertia
        ixx="0.836174315731899"
        ixy="-0.000182558276359213"
        ixz="0.00132925805770279"
        iyy="0.720303102414471"
        iyz="-0.000258706744252241"
        izz="0.722870275760771" />
    </inertial>
    <visual>
      <origin
        xyz="0 0 0"
        rpy="0 0 0" />
      <geometry>
        <mesh
          filename="package://matrix_true_description/meshes/base_link.STL" />
      </geometry>
      <material
        name="">
        <color
          rgba="0.752941176470588 0.752941176470588 0.752941176470588 1" />
      </material>
    </visual>
    <collision>
      <origin
        xyz="0 0 0"
        rpy="0 0 0" />
      <geometry>
        <mesh
          filename="package://matrix_true_description/meshes/base_link.STL" />
      </geometry>
    </collision>
  </link>
  <link
    name="wheel_right_link">
    <inertial>
      <origin
        xyz="-1.3878E-17 0.00082541 2.7905E-10"
        rpy="0 0 0" />
      <mass
        value="1.2499" />
      <inertia
        ixx="0.0023164"
        ixy="-7.259E-19"
        ixz="-9.0858E-26"
        iyy="0.0038673"
        iyz="3.5318E-10"
        izz="0.0023164" />
    </inertial>
    <visual>
      <origin
        xyz="0 0 0"
        rpy="0 0 0" />
      <geometry>
        <mesh
          filename="package://matrix_true_description/meshes/wheel_right_link.STL" />
      </geometry>
      <material
        name="">
        <color
          rgba="0.79216 0.81961 0.93333 1" />
      </material>
    </visual>
    <collision>
      <origin
        xyz="0 0 0"
        rpy="0 0 0" />
      <geometry>
        <mesh
          filename="package://matrix_true_description/meshes/wheel_right_link.STL" />
      </geometry>
    </collision>
  </link>
  <joint
    name="wheel_right_joint"
    type="continuous">
    <origin
      xyz="0.00370810119881812 -0.2171 0.0850001069853645"
      rpy="0 1.5707963267949 0" />
    <parent
      link="base_link" />
    <child
      link="wheel_right_link" />
    <axis
      xyz="0 -1 0" />
    <limit
      effort="8"
      velocity="20.944" />
  </joint>
  <link
    name="wheel_left_link">
    <inertial>
      <origin
        xyz="2.579E-10 -0.00082541 -1.0655E-10"
        rpy="0 0 0" />
      <mass
        value="1.2499" />
      <inertia
        ixx="0.0023164"
        ixy="-3.2641E-10"
        ixz="7.6444E-20"
        iyy="0.0038673"
        iyz="1.3486E-10"
        izz="0.0023164" />
    </inertial>
    <visual>
      <origin
        xyz="0 0 0"
        rpy="0 0 0" />
      <geometry>
        <mesh
          filename="package://matrix_true_description/meshes/wheel_left_link.STL" />
      </geometry>
      <material
        name="">
        <color
          rgba="0.79216 0.81961 0.93333 1" />
      </material>
    </visual>
    <collision>
      <origin
        xyz="0 0 0"
        rpy="0 0 0" />
      <geometry>
        <mesh
          filename="package://matrix_true_description/meshes/wheel_left_link.STL" />
      </geometry>
    </collision>
  </link>
  <joint
    name="wheel_left_right"
    type="continuous">
    <origin
      xyz="0.0037081011988188 0.2171 0.0850001069853643"
      rpy="0 1.5707963267949 0" />
    <parent
      link="base_link" />
    <child
      link="wheel_left_link" />
    <axis
      xyz="0 1 0" />
    <limit
      effort="8"
      velocity="20.944" />
  </joint>
  <link
    name="caster_arm_fr_link">
    <inertial>
      <origin
        xyz="-0.0049485 9.0737E-05 -0.011133"
        rpy="0 0 0" />
      <mass
        value="0.022869" />
      <inertia
        ixx="5.467E-06"
        ixy="1.0185E-09"
        ixz="-1.276E-06"
        iyy="5.6833E-06"
        iyz="9.1538E-10"
        izz="5.7221E-06" />
    </inertial>
    <visual>
      <origin
        xyz="0 0 0"
        rpy="0 0 0" />
      <geometry>
        <mesh
          filename="package://matrix_true_description/meshes/caster_arm_fr_link.STL" />
      </geometry>
      <material
        name="">
        <color
          rgba="0.79216 0.81961 0.93333 1" />
      </material>
    </visual>
    <collision>
      <origin
        xyz="0 0 0"
        rpy="0 0 0" />
      <geometry>
        <mesh
          filename="package://matrix_true_description/meshes/caster_arm_fr_link.STL" />
      </geometry>
    </collision>
  </link>
  <joint
    name="caster_arm_fr_joint"
    type="continuous">
    <origin
      xyz="0.175000000000001 -0.0999999999999988 0.069116"
      rpy="0 0 0" />
    <parent
      link="base_link" />
    <child
      link="caster_arm_fr_link" />
    <axis
      xyz="0 0 1" />
  </joint>
  <link
    name="caster_wheel_fr_link">
    <inertial>
      <origin
        xyz="2.4597E-08 -1.0921E-09 -7.5675E-09"
        rpy="0 0 0" />
      <mass
        value="0.037215" />
      <inertia
        ixx="6.8378E-06"
        ixy="7.8988E-12"
        ixz="-5.3162E-11"
        iyy="1.1315E-05"
        iyz="-2.084E-12"
        izz="6.8374E-06" />
    </inertial>
    <visual>
      <origin
        xyz="0 0 0"
        rpy="0 0 0" />
      <geometry>
        <mesh
          filename="package://matrix_true_description/meshes/caster_wheel_fr_link.STL" />
      </geometry>
      <material
        name="">
        <color
          rgba="0.79216 0.81961 0.93333 1" />
      </material>
    </visual>
    <collision>
      <origin
        xyz="0 0 0"
        rpy="0 0 0" />
      <geometry>
        <mesh
          filename="package://matrix_true_description/meshes/caster_wheel_fr_link.STL" />
      </geometry>
    </collision>
  </link>
  <joint
    name="caster_wheel_fr_joint"
    type="continuous">
    <origin
      xyz="-0.0250000000000008 0 -0.044"
      rpy="0 1.5707963267949 0" />
    <parent
      link="caster_arm_fr_link" />
    <child
      link="caster_wheel_fr_link" />
    <axis
      xyz="0 1 0" />
  </joint>
  <link
    name="caster_arm_fl_link">
    <inertial>
      <origin
        xyz="-0.0049485 9.0737E-05 -0.011133"
        rpy="0 0 0" />
      <mass
        value="0.022869" />
      <inertia
        ixx="5.467E-06"
        ixy="1.0185E-09"
        ixz="-1.276E-06"
        iyy="5.6833E-06"
        iyz="9.1539E-10"
        izz="5.7221E-06" />
    </inertial>
    <visual>
      <origin
        xyz="0 0 0"
        rpy="0 0 0" />
      <geometry>
        <mesh
          filename="package://matrix_true_description/meshes/caster_arm_fl_link.STL" />
      </geometry>
      <material
        name="">
        <color
          rgba="0.79216 0.81961 0.93333 1" />
      </material>
    </visual>
    <collision>
      <origin
        xyz="0 0 0"
        rpy="0 0 0" />
      <geometry>
        <mesh
          filename="package://matrix_true_description/meshes/caster_arm_fl_link.STL" />
      </geometry>
    </collision>
  </link>
  <joint
    name="caster_arm_fl_joint"
    type="continuous">
    <origin
      xyz="0.174999999999999 0.100000000000001 0.069116"
      rpy="0 0 0" />
    <parent
      link="base_link" />
    <child
      link="caster_arm_fl_link" />
    <axis
      xyz="0 0 1" />
  </joint>
  <link
    name="caster_wheel_fl_link">
    <inertial>
      <origin
        xyz="2.4597E-08 -1.0921E-09 -7.5675E-09"
        rpy="0 0 0" />
      <mass
        value="0.037215" />
      <inertia
        ixx="6.8378E-06"
        ixy="7.8988E-12"
        ixz="-5.3162E-11"
        iyy="1.1315E-05"
        iyz="-2.084E-12"
        izz="6.8374E-06" />
    </inertial>
    <visual>
      <origin
        xyz="0 0 0"
        rpy="0 0 0" />
      <geometry>
        <mesh
          filename="package://matrix_true_description/meshes/caster_wheel_fl_link.STL" />
      </geometry>
      <material
        name="">
        <color
          rgba="0.79216 0.81961 0.93333 1" />
      </material>
    </visual>
    <collision>
      <origin
        xyz="0 0 0"
        rpy="0 0 0" />
      <geometry>
        <mesh
          filename="package://matrix_true_description/meshes/caster_wheel_fl_link.STL" />
      </geometry>
    </collision>
  </link>
  <joint
    name="caster_wheel_fl_joint"
    type="continuous">
    <origin
      xyz="-0.0249999999999994 0 -0.0439999999999999"
      rpy="0 1.5707963267949 0" />
    <parent
      link="caster_arm_fl_link" />
    <child
      link="caster_wheel_fl_link" />
    <axis
      xyz="0 1 0" />
  </joint>
  <link
    name="caster_arm_rr_link">
    <inertial>
      <origin
        xyz="-0.0049485 9.0737E-05 -0.011133"
        rpy="0 0 0" />
      <mass
        value="0.022869" />
      <inertia
        ixx="5.467E-06"
        ixy="1.0185E-09"
        ixz="-1.276E-06"
        iyy="5.6833E-06"
        iyz="9.1538E-10"
        izz="5.7221E-06" />
    </inertial>
    <visual>
      <origin
        xyz="0 0 0"
        rpy="0 0 0" />
      <geometry>
        <mesh
          filename="package://matrix_true_description/meshes/caster_arm_rr_link.STL" />
      </geometry>
      <material
        name="">
        <color
          rgba="0.79216 0.81961 0.93333 1" />
      </material>
    </visual>
    <collision>
      <origin
        xyz="0 0 0"
        rpy="0 0 0" />
      <geometry>
        <mesh
          filename="package://matrix_true_description/meshes/caster_arm_rr_link.STL" />
      </geometry>
    </collision>
  </link>
  <joint
    name="caster_arm_rr_joint"
    type="continuous">
    <origin
      xyz="-0.174999999999999 -0.100000000000001 0.069116"
      rpy="0 0 0" />
    <parent
      link="base_link" />
    <child
      link="caster_arm_rr_link" />
    <axis
      xyz="0 0 1" />
  </joint>
  <link
    name="caster_wheel_rr_link">
    <inertial>
      <origin
        xyz="2.4597E-08 -1.0921E-09 -7.5675E-09"
        rpy="0 0 0" />
      <mass
        value="0.037215" />
      <inertia
        ixx="6.8378E-06"
        ixy="7.8988E-12"
        ixz="-5.3162E-11"
        iyy="1.1315E-05"
        iyz="-2.084E-12"
        izz="6.8374E-06" />
    </inertial>
    <visual>
      <origin
        xyz="0 0 0"
        rpy="0 0 0" />
      <geometry>
        <mesh
          filename="package://matrix_true_description/meshes/caster_wheel_rr_link.STL" />
      </geometry>
      <material
        name="">
        <color
          rgba="0.79216 0.81961 0.93333 1" />
      </material>
    </visual>
    <collision>
      <origin
        xyz="0 0 0"
        rpy="0 0 0" />
      <geometry>
        <mesh
          filename="package://matrix_true_description/meshes/caster_wheel_rr_link.STL" />
      </geometry>
    </collision>
  </link>
  <joint
    name="caster_wheel_rr_joint"
    type="continuous">
    <origin
      xyz="-0.0250000000000008 0 -0.044"
      rpy="0 1.5707963267949 0" />
    <parent
      link="caster_arm_rr_link" />
    <child
      link="caster_wheel_rr_link" />
    <axis
      xyz="0 1 0" />
  </joint>
  <link
    name="caster_arm_rl_link">
    <inertial>
      <origin
        xyz="-0.0049485 9.0737E-05 -0.011133"
        rpy="0 0 0" />
      <mass
        value="0.022869" />
      <inertia
        ixx="5.467E-06"
        ixy="1.0185E-09"
        ixz="-1.276E-06"
        iyy="5.6833E-06"
        iyz="9.1538E-10"
        izz="5.7221E-06" />
    </inertial>
    <visual>
      <origin
        xyz="0 0 0"
        rpy="0 0 0" />
      <geometry>
        <mesh
          filename="package://matrix_true_description/meshes/caster_arm_rl_link.STL" />
      </geometry>
      <material
        name="">
        <color
          rgba="0.79216 0.81961 0.93333 1" />
      </material>
    </visual>
    <collision>
      <origin
        xyz="0 0 0"
        rpy="0 0 0" />
      <geometry>
        <mesh
          filename="package://matrix_true_description/meshes/caster_arm_rl_link.STL" />
      </geometry>
    </collision>
  </link>
  <joint
    name="caster_arm_rl_joint"
    type="continuous">
    <origin
      xyz="-0.175000000000001 0.0999999999999989 0.069116"
      rpy="0 0 0" />
    <parent
      link="base_link" />
    <child
      link="caster_arm_rl_link" />
    <axis
      xyz="0 0 1" />
  </joint>
  <link
    name="caster_wheel_rl_link">
    <inertial>
      <origin
        xyz="2.4597E-08 -1.0921E-09 -7.5675E-09"
        rpy="0 0 0" />
      <mass
        value="0.037215" />
      <inertia
        ixx="6.8378E-06"
        ixy="7.8988E-12"
        ixz="-5.3162E-11"
        iyy="1.1315E-05"
        iyz="-2.084E-12"
        izz="6.8374E-06" />
    </inertial>
    <visual>
      <origin
        xyz="0 0 0"
        rpy="0 0 0" />
      <geometry>
        <mesh
          filename="package://matrix_true_description/meshes/caster_wheel_rl_link.STL" />
      </geometry>
      <material
        name="">
        <color
          rgba="0.79216 0.81961 0.93333 1" />
      </material>
    </visual>
    <collision>
      <origin
        xyz="0 0 0"
        rpy="0 0 0" />
      <geometry>
        <mesh
          filename="package://matrix_true_description/meshes/caster_wheel_rl_link.STL" />
      </geometry>
    </collision>
  </link>
  <joint
    name="caster_wheel_rl_joint"
    type="continuous">
    <origin
      xyz="-0.0249999999999994 0 -0.0439999999999999"
      rpy="0 1.5707963267949 0" />
    <parent
      link="caster_arm_rl_link" />
    <child
      link="caster_wheel_rl_link" />
    <axis
      xyz="0 1 0" />
  </joint>
  <link
    name="imu_link">
    <inertial>
      <origin
        xyz="0.00044188 -0.00010543 -0.0015868"
        rpy="0 0 0" />
      <mass
        value="0.00098313" />
      <inertia
        ixx="2.7278E-08"
        ixy="1.8646E-11"
        ixz="1.8314E-11"
        iyy="4.8045E-08"
        iyz="1.8158E-12"
        izz="7.4856E-08" />
    </inertial>
    <visual>
      <origin
        xyz="0 0 0"
        rpy="0 0 0" />
      <geometry>
        <mesh
          filename="package://matrix_true_description/meshes/imu_link.STL" />
      </geometry>
      <material
        name="">
        <color
          rgba="0.79216 0.81961 0.93333 1" />
      </material>
    </visual>
    <collision>
      <origin
        xyz="0 0 0"
        rpy="0 0 0" />
      <geometry>
        <mesh
          filename="package://matrix_true_description/meshes/imu_link.STL" />
      </geometry>
    </collision>
  </link>
  <joint
    name="imu_joint"
    type="fixed">
    <origin
      xyz="-0.020000000000002 0 0.347116"
      rpy="0 0 0" />
    <parent
      link="base_link" />
    <child
      link="imu_link" />
    <axis
      xyz="0 0 0" />
  </joint>
  <link
    name="lidar_merged_link">
    <inertial>
      <origin
        xyz="0.0029904 1.4355E-05 -0.013984"
        rpy="0 0 0" />
      <mass
        value="0.047984" />
      <inertia
        ixx="2.505E-05"
        ixy="5.7803E-09"
        ixz="1.4459E-08"
        iyy="2.6771E-05"
        iyz="9.2353E-10"
        izz="4.8899E-05" />
    </inertial>
    <visual>
      <origin
        xyz="0 0 0"
        rpy="0 0 0" />
      <geometry>
        <mesh
          filename="package://matrix_true_description/meshes/lidar_merged_link.STL" />
      </geometry>
      <material
        name="">
        <color
          rgba="0.49804 0.49804 0.49804 1" />
      </material>
    </visual>
    <collision>
      <origin
        xyz="0 0 0"
        rpy="0 0 0" />
      <geometry>
        <mesh
          filename="package://matrix_true_description/meshes/lidar_merged_link.STL" />
      </geometry>
    </collision>
  </link>
  <joint
    name="lidar_merged_joint"
    type="fixed">
    <origin
      xyz="0.155000000000003 0 0.295715793055286"
      rpy="0 0 3.14159265358979" />
    <parent
      link="base_link" />
    <child
      link="lidar_merged_link" />
    <axis
      xyz="0 0 0" />
  </joint>
  <link
    name="depth_cam_mount_point_link">
    <inertial>
      <origin
        xyz="0.0015077 0.001406 0.012477"
        rpy="0 0 0" />
      <mass
        value="0.036472" />
      <inertia
        ixx="2.3403E-05"
        ixy="2.1029E-07"
        ixz="1.0154E-08"
        iyy="3.5061E-06"
        iyz="1.7263E-09"
        izz="2.3612E-05" />
    </inertial>
    <visual>
      <origin
        xyz="0 0 0"
        rpy="0 0 0" />
      <geometry>
        <mesh
          filename="package://matrix_true_description/meshes/depth_cam_mount_point_link.STL" />
      </geometry>
      <material
        name="">
        <color
          rgba="0.79216 0.81961 0.93333 1" />
      </material>
    </visual>
    <collision>
      <origin
        xyz="0 0 0"
        rpy="0 0 0" />
      <geometry>
        <mesh
          filename="package://matrix_true_description/meshes/depth_cam_mount_point_link.STL" />
      </geometry>
    </collision>
  </link>
  <joint
    name="depth_cam_mount_point_joint"
    type="fixed">
    <origin
      xyz="0.145649999999998 0 0.480116"
      rpy="0 0 0" />
    <parent
      link="base_link" />
    <child
      link="depth_cam_mount_point_link" />
    <axis
      xyz="0 0 0" />
  </joint>
  <link
    name="ultrasonic_fr_link">
    <inertial>
      <origin
        xyz="-0.016663 0.00013386 -0.00013337"
        rpy="0 0 0" />
      <mass
        value="0.0027745" />
      <inertia
        ixx="2.7422E-07"
        ixy="-1.3928E-08"
        ixz="-2.1173E-09"
        iyy="7.0079E-08"
        iyz="-1.2294E-11"
        izz="2.5957E-07" />
    </inertial>
    <visual>
      <origin
        xyz="0 0 0"
        rpy="0 0 0" />
      <geometry>
        <mesh
          filename="package://matrix_true_description/meshes/ultrasonic_fr_link.STL" />
      </geometry>
      <material
        name="">
        <color
          rgba="0.79216 0.81961 0.93333 1" />
      </material>
    </visual>
    <collision>
      <origin
        xyz="0 0 0"
        rpy="0 0 0" />
      <geometry>
        <mesh
          filename="package://matrix_true_description/meshes/ultrasonic_fr_link.STL" />
      </geometry>
    </collision>
  </link>
  <joint
    name="ultrasonic_fr_joint"
    type="fixed">
    <origin
      xyz="0.169517824893003 -0.168095327438868 0.234077654834356"
      rpy="0 0.00199498585800991 -0.717281737993582" />
    <parent
      link="base_link" />
    <child
      link="ultrasonic_fr_link" />
    <axis
      xyz="0 0 0" />
  </joint>
  <link
    name="ultrasonic_fc_link">
    <inertial>
      <origin
        xyz="-0.014549 5.6224E-06 -0.0001367"
        rpy="0 0 0" />
      <mass
        value="0.0027745" />
      <inertia
        ixx="2.7523E-07"
        ixy="6.4822E-11"
        ixz="-1.8546E-09"
        iyy="6.9133E-08"
        iyz="-1.2947E-10"
        izz="2.5951E-07" />
    </inertial>
    <visual>
      <origin
        xyz="0 0 0"
        rpy="0 0 0" />
      <geometry>
        <mesh
          filename="package://matrix_true_description/meshes/ultrasonic_fc_link.STL" />
      </geometry>
      <material
        name="">
        <color
          rgba="0.79216 0.81961 0.93333 1" />
      </material>
    </visual>
    <collision>
      <origin
        xyz="0 0 0"
        rpy="0 0 0" />
      <geometry>
        <mesh
          filename="package://matrix_true_description/meshes/ultrasonic_fc_link.STL" />
      </geometry>
    </collision>
  </link>
  <joint
    name="ultrasonic_fc_joint"
    type="fixed">
    <origin
      xyz="0.212644504488986 0 0.2338466055562"
      rpy="0 0.0183935250864792 0" />
    <parent
      link="base_link" />
    <child
      link="ultrasonic_fc_link" />
    <axis
      xyz="0 0 0" />
  </joint>
  <link
    name="ultrasonic_fl_link">
    <inertial>
      <origin
        xyz="-0.016662 -0.00014064 -0.00013413"
        rpy="0 0 0" />
      <mass
        value="0.0027745" />
      <inertia
        ixx="2.742E-07"
        ixy="1.4092E-08"
        ixz="-2.1038E-09"
        iyy="7.0101E-08"
        iyz="-2.5261E-10"
        izz="2.5957E-07" />
    </inertial>
    <visual>
      <origin
        xyz="0 0 0"
        rpy="0 0 0" />
      <geometry>
        <mesh
          filename="package://matrix_true_description/meshes/ultrasonic_fl_link.STL" />
      </geometry>
      <material
        name="">
        <color
          rgba="0.79216 0.81961 0.93333 1" />
      </material>
    </visual>
    <collision>
      <origin
        xyz="0 0 0"
        rpy="0 0 0" />
      <geometry>
        <mesh
          filename="package://matrix_true_description/meshes/ultrasonic_fl_link.STL" />
      </geometry>
    </collision>
  </link>
  <joint
    name="ultrasonic_fl_joint"
    type="fixed">
    <origin
      xyz="0.169519435902909 0.168093291552763 0.234083315247261"
      rpy="0 0.00170059039625006 0.717087904309002" />
    <parent
      link="base_link" />
    <child
      link="ultrasonic_fl_link" />
    <axis
      xyz="0 0 0" />
  </joint>
  <link
    name="rear_camera_link">
    <inertial>
      <origin
        xyz="-0.029671 0.00028258 0.00045378"
        rpy="0 0 0" />
      <mass
        value="0.12773" />
      <inertia
        ixx="4.9543E-05"
        ixy="1.9659E-21"
        ixz="-2.7639E-22"
        iyy="4.964E-05"
        iyz="2.2169E-21"
        izz="4.9782E-05" />
    </inertial>
    <visual>
      <origin
        xyz="0 0 0"
        rpy="0 0 0" />
      <geometry>
        <mesh
          filename="package://matrix_true_description/meshes/rear_camera_link.STL" />
      </geometry>
      <material
        name="">
        <color
          rgba="1 1 1 1" />
      </material>
    </visual>
    <collision>
      <origin
        xyz="0 0 0"
        rpy="0 0 0" />
      <geometry>
        <mesh
          filename="package://matrix_true_description/meshes/rear_camera_link.STL" />
      </geometry>
    </collision>
  </link>
  <joint
    name="rear_camera_joint"
    type="fixed">
    <origin
      xyz="-0.111753499872574 0 0.041116"
      rpy="0 0 -3.14159265358979" />
    <parent
      link="base_link" />
    <child
      link="rear_camera_link" />
    <axis
      xyz="0 0 0" />
  </joint>
</robot>