<?xml version="1.0" encoding="utf-8"?>
<!-- This URDF was automatically created by SolidWorks to URDF Exporter! Originally created by Stephen Brawner (brawner@gmail.com) 
     Commit Version: 1.6.0-4-g7f85cfe  Build Version: 1.6.7995.38578
     For more information, please see http://wiki.ros.org/sw_urdf_exporter -->
<robot
  name="matrix_true_description">
  <link
    name="base_link">
    <inertial>
      <origin
        xyz="-0.0193327740236748 0.000357362284587356 0.302224740304159"
        rpy="0 0 0" />
      <mass
        value="95.4830322905057" />
      <inertia
        ixx="0.836174315731897"
        ixy="-0.000182558276359232"
        ixz="0.00132925805770272"
        iyy="0.720303102414471"
        iyz="-0.00025870674425222"
        izz="0.722870275760771" />
    </inertial>
    <visual>
      <origin
        xyz="0 0 0"
        rpy="0 0 0" />
      <geometry>
        <mesh
          filename="package://matrix_true_description/meshes/base_link.STL" />
      </geometry>
      <material
        name="">
        <color
          rgba="0.752941176470588 0.752941176470588 0.752941176470588 1" />
      </material>
    </visual>
    <collision>
      <origin
        xyz="0 0 0"
        rpy="0 0 0" />
      <geometry>
        <mesh
          filename="package://matrix_true_description/meshes/base_link.STL" />
      </geometry>
    </collision>
  </link>
  <link
    name="wheel_right_link">
    <inertial>
      <origin
        xyz="-1.3878E-17 0.00082541 2.7905E-10"
        rpy="0 0 0" />
      <mass
        value="1.2499" />
      <inertia
        ixx="0.0023164"
        ixy="-7.259E-19"
        ixz="-9.0858E-26"
        iyy="0.0038673"
        iyz="3.5318E-10"
        izz="0.0023164" />
    </inertial>
    <visual>
      <origin
        xyz="0 0 0"
        rpy="0 0 0" />
      <geometry>
        <mesh
          filename="package://matrix_true_description/meshes/wheel_right_link.STL" />
      </geometry>
      <material
        name="">
        <color
          rgba="0.79216 0.81961 0.93333 1" />
      </material>
    </visual>
    <collision>
      <origin
        xyz="0 0 0"
        rpy="0 0 0" />
      <geometry>
        <mesh
          filename="package://matrix_true_description/meshes/wheel_right_link.STL" />
      </geometry>
    </collision>
  </link>
  <joint
    name="wheel_right_joint"
    type="continuous">
    <origin
      xyz="0.0037081 -0.2171 0.085"
      rpy="0 1.5708 0" />
    <parent
      link="base_link" />
    <child
      link="wheel_right_link" />
    <axis
      xyz="0 -1 0" />
    <limit
      effort="8"
      velocity="20.944" />
  </joint>
  <link
    name="wheel_left_link">
    <inertial>
      <origin
        xyz="2.579E-10 -0.00082541 -1.0655E-10"
        rpy="0 0 0" />
      <mass
        value="1.2499" />
      <inertia
        ixx="0.0023164"
        ixy="-3.2641E-10"
        ixz="7.6444E-20"
        iyy="0.0038673"
        iyz="1.3486E-10"
        izz="0.0023164" />
    </inertial>
    <visual>
      <origin
        xyz="0 0 0"
        rpy="0 0 0" />
      <geometry>
        <mesh
          filename="package://matrix_true_description/meshes/wheel_left_link.STL" />
      </geometry>
      <material
        name="">
        <color
          rgba="0.79216 0.81961 0.93333 1" />
      </material>
    </visual>
    <collision>
      <origin
        xyz="0 0 0"
        rpy="0 0 0" />
      <geometry>
        <mesh
          filename="package://matrix_true_description/meshes/wheel_left_link.STL" />
      </geometry>
    </collision>
  </link>
  <joint
    name="wheel_left_right"
    type="continuous">
    <origin
      xyz="0.0037081 0.2171 0.085"
      rpy="0 1.5708 0" />
    <parent
      link="base_link" />
    <child
      link="wheel_left_link" />
    <axis
      xyz="0 1 0" />
    <limit
      effort="8"
      velocity="20.944" />
  </joint>
  <link
    name="caster_arm_fr_link">
    <inertial>
      <origin
        xyz="-0.004948472384154 9.07365737506938E-05 -0.0111326023748811"
        rpy="0 0 0" />
      <mass
        value="0.0228689686633764" />
      <inertia
        ixx="5.46701773628797E-06"
        ixy="1.01849600726378E-09"
        ixz="-1.27604972644686E-06"
        iyy="5.68327410624464E-06"
        iyz="9.1538389701251E-10"
        izz="5.72207125871922E-06" />
    </inertial>
    <visual>
      <origin
        xyz="0 0 0"
        rpy="0 0 0" />
      <geometry>
        <mesh
          filename="package://matrix_true_description/meshes/caster_arm_fr_link.STL" />
      </geometry>
      <material
        name="">
        <color
          rgba="0.792156862745098 0.819607843137255 0.933333333333333 1" />
      </material>
    </visual>
    <collision>
      <origin
        xyz="0 0 0"
        rpy="0 0 0" />
      <geometry>
        <mesh
          filename="package://matrix_true_description/meshes/caster_arm_fr_link.STL" />
      </geometry>
    </collision>
  </link>
  <joint
    name="caster_arm_fr_joint"
    type="continuous">
    <origin
      xyz="0.175 -0.1 0.069116"
      rpy="0 0 0" />
    <parent
      link="base_link" />
    <child
      link="caster_arm_fr_link" />
    <axis
      xyz="0 0 1" />
  </joint>
  <link
    name="caster_wheel_fr_link">
    <inertial>
      <origin
        xyz="2.45965642159396E-08 -1.09211185927993E-09 -7.56747059460494E-09"
        rpy="0 0 0" />
      <mass
        value="0.0372150073615411" />
      <inertia
        ixx="6.83775386210628E-06"
        ixy="7.89881207654632E-12"
        ixz="-5.31617220528368E-11"
        iyy="1.13150193462786E-05"
        iyz="-2.08401338263005E-12"
        izz="6.83739570177949E-06" />
    </inertial>
    <visual>
      <origin
        xyz="0 0 0"
        rpy="0 0 0" />
      <geometry>
        <mesh
          filename="package://matrix_true_description/meshes/caster_wheel_fr_link.STL" />
      </geometry>
      <material
        name="">
        <color
          rgba="0.792156862745098 0.819607843137255 0.933333333333333 1" />
      </material>
    </visual>
    <collision>
      <origin
        xyz="0 0 0"
        rpy="0 0 0" />
      <geometry>
        <mesh
          filename="package://matrix_true_description/meshes/caster_wheel_fr_link.STL" />
      </geometry>
    </collision>
  </link>
  <joint
    name="caster_wheel_fr_joint"
    type="continuous">
    <origin
      xyz="-0.0250000000000008 0 -0.044"
      rpy="0 1.5707963267949 0" />
    <parent
      link="caster_arm_fr_link" />
    <child
      link="caster_wheel_fr_link" />
    <axis
      xyz="0 1 0" />
  </joint>
  <link
    name="caster_arm_fl_link">
    <inertial>
      <origin
        xyz="-0.00494847237322624 9.07365856944176E-05 -0.0111326023668961"
        rpy="0 0 0" />
      <mass
        value="0.0228689686367412" />
      <inertia
        ixx="5.46701773241529E-06"
        ixy="1.01849887753651E-09"
        ixz="-1.27604972508027E-06"
        iyy="5.68327410249645E-06"
        iyz="9.15385255496975E-10"
        izz="5.72207125297098E-06" />
    </inertial>
    <visual>
      <origin
        xyz="0 0 0"
        rpy="0 0 0" />
      <geometry>
        <mesh
          filename="package://matrix_true_description/meshes/caster_arm_fl_link.STL" />
      </geometry>
      <material
        name="">
        <color
          rgba="0.792156862745098 0.819607843137255 0.933333333333333 1" />
      </material>
    </visual>
    <collision>
      <origin
        xyz="0 0 0"
        rpy="0 0 0" />
      <geometry>
        <mesh
          filename="package://matrix_true_description/meshes/caster_arm_fl_link.STL" />
      </geometry>
    </collision>
  </link>
  <joint
    name="caster_arm_fl_joint"
    type="continuous">
    <origin
      xyz="0.175 0.1 0.069116"
      rpy="0 0 0" />
    <parent
      link="base_link" />
    <child
      link="caster_arm_fl_link" />
    <axis
      xyz="0 0 1" />
  </joint>
  <link
    name="caster_wheel_fl_link">
    <inertial>
      <origin
        xyz="-0.02500000756747 -1.09211677201682E-09 -0.0440000245965642"
        rpy="0 0 0" />
      <mass
        value="0.0372150073615411" />
      <inertia
        ixx="6.8373957017795E-06"
        ixy="-2.08401386491503E-12"
        ixz="5.31617220532651E-11"
        iyy="1.13150193462786E-05"
        iyz="-7.89881207210336E-12"
        izz="6.83775386210629E-06" />
    </inertial>
    <visual>
      <origin
        xyz="0 0 0"
        rpy="0 0 0" />
      <geometry>
        <mesh
          filename="package://matrix_true_description/meshes/caster_wheel_fl_link.STL" />
      </geometry>
      <material
        name="">
        <color
          rgba="0.792156862745098 0.819607843137255 0.933333333333333 1" />
      </material>
    </visual>
    <collision>
      <origin
        xyz="0 0 0"
        rpy="0 0 0" />
      <geometry>
        <mesh
          filename="package://matrix_true_description/meshes/caster_wheel_fl_link.STL" />
      </geometry>
    </collision>
  </link>
  <joint
    name="caster_wheel_fl_joint"
    type="continuous">
    <origin
      xyz="0 0 0"
      rpy="0 0 0" />
    <parent
      link="caster_arm_fl_link" />
    <child
      link="caster_wheel_fl_link" />
    <axis
      xyz="0 0 1" />
  </joint>
  <link
    name="caster_arm_rr_link">
    <inertial>
      <origin
        xyz="-0.00494847237322321 9.07365856944453E-05 -0.011132602366896"
        rpy="0 0 0" />
      <mass
        value="0.0228689686367412" />
      <inertia
        ixx="5.46701773241533E-06"
        ixy="1.01849887752167E-09"
        ixz="-1.2760497250803E-06"
        iyy="5.68327410249646E-06"
        iyz="9.15385255515465E-10"
        izz="5.72207125297098E-06" />
    </inertial>
    <visual>
      <origin
        xyz="0 0 0"
        rpy="0 0 0" />
      <geometry>
        <mesh
          filename="package://matrix_true_description/meshes/caster_arm_rr_link.STL" />
      </geometry>
      <material
        name="">
        <color
          rgba="0.792156862745098 0.819607843137255 0.933333333333333 1" />
      </material>
    </visual>
    <collision>
      <origin
        xyz="0 0 0"
        rpy="0 0 0" />
      <geometry>
        <mesh
          filename="package://matrix_true_description/meshes/caster_arm_rr_link.STL" />
      </geometry>
    </collision>
  </link>
  <joint
    name="caster_arm_rr_joint"
    type="continuous">
    <origin
      xyz="-0.175 -0.1 0.069116"
      rpy="0 0 0" />
    <parent
      link="base_link" />
    <child
      link="caster_arm_rr_link" />
    <axis
      xyz="0 0 1" />
  </joint>
  <link
    name="caster_wheel_rr_link">
    <inertial>
      <origin
        xyz="2.45965641812451E-08 -1.09211184540214E-09 -7.56747059460494E-09"
        rpy="0 0 0" />
      <mass
        value="0.0372150073615412" />
      <inertia
        ixx="6.83775386210632E-06"
        ixy="7.89881208189957E-12"
        ixz="-5.31617220528368E-11"
        iyy="1.13150193462787E-05"
        iyz="-2.08401338263005E-12"
        izz="6.83739570177952E-06" />
    </inertial>
    <visual>
      <origin
        xyz="0 0 0"
        rpy="0 0 0" />
      <geometry>
        <mesh
          filename="package://matrix_true_description/meshes/caster_wheel_rr_link.STL" />
      </geometry>
      <material
        name="">
        <color
          rgba="0.792156862745098 0.819607843137255 0.933333333333333 1" />
      </material>
    </visual>
    <collision>
      <origin
        xyz="0 0 0"
        rpy="0 0 0" />
      <geometry>
        <mesh
          filename="package://matrix_true_description/meshes/caster_wheel_rr_link.STL" />
      </geometry>
    </collision>
  </link>
  <joint
    name="caster_wheel_rr_joint"
    type="continuous">
    <origin
      xyz="-0.0250000000000008 0 -0.044"
      rpy="0 1.5707963267949 0" />
    <parent
      link="caster_arm_rr_link" />
    <child
      link="caster_wheel_rr_link" />
    <axis
      xyz="0 1 0" />
  </joint>
  <link
    name="caster_arm_rl_link">
    <inertial>
      <origin
        xyz="-0.00494847238283191 9.07365753418238E-05 -0.011132602373886"
        rpy="0 0 0" />
      <mass
        value="0.0228689686598223" />
      <inertia
        ixx="5.46701773578954E-06"
        ixy="1.0184963559904E-09"
        ixz="-1.27604972629729E-06"
        iyy="5.68327410582607E-06"
        iyz="9.15384060083569E-10"
        izz="5.72207125801831E-06" />
    </inertial>
    <visual>
      <origin
        xyz="0 0 0"
        rpy="0 0 0" />
      <geometry>
        <mesh
          filename="package://matrix_true_description/meshes/caster_arm_rl_link.STL" />
      </geometry>
      <material
        name="">
        <color
          rgba="0.792156862745098 0.819607843137255 0.933333333333333 1" />
      </material>
    </visual>
    <collision>
      <origin
        xyz="0 0 0"
        rpy="0 0 0" />
      <geometry>
        <mesh
          filename="package://matrix_true_description/meshes/caster_arm_rl_link.STL" />
      </geometry>
    </collision>
  </link>
  <joint
    name="caster_arm_rl_joint"
    type="continuous">
    <origin
      xyz="-0.175 0.1 0.069116"
      rpy="0 0 0" />
    <parent
      link="base_link" />
    <child
      link="caster_arm_rl_link" />
    <axis
      xyz="0 0 1" />
  </joint>
  <link
    name="caster_wheel_rl_link">
    <inertial>
      <origin
        xyz="2.45965641465506E-08 -1.09211185927993E-09 -7.56747059460494E-09"
        rpy="0 0 0" />
      <mass
        value="0.0372150073615412" />
      <inertia
        ixx="6.83775386210631E-06"
        ixy="7.89881208046977E-12"
        ixz="-5.31617220532634E-11"
        iyy="1.13150193462787E-05"
        iyz="-2.08401338252726E-12"
        izz="6.83739570177952E-06" />
    </inertial>
    <visual>
      <origin
        xyz="0 0 0"
        rpy="0 0 0" />
      <geometry>
        <mesh
          filename="package://matrix_true_description/meshes/caster_wheel_rl_link.STL" />
      </geometry>
      <material
        name="">
        <color
          rgba="0.792156862745098 0.819607843137255 0.933333333333333 1" />
      </material>
    </visual>
    <collision>
      <origin
        xyz="0 0 0"
        rpy="0 0 0" />
      <geometry>
        <mesh
          filename="package://matrix_true_description/meshes/caster_wheel_rl_link.STL" />
      </geometry>
    </collision>
  </link>
  <joint
    name="caster_wheel_rl_joint"
    type="continuous">
    <origin
      xyz="-0.0249999999999994 0 -0.0439999999999999"
      rpy="0 1.5707963267949 0" />
    <parent
      link="caster_arm_rl_link" />
    <child
      link="caster_wheel_rl_link" />
    <axis
      xyz="0 1 0" />
  </joint>
  <link
    name="imu_link">
    <inertial>
      <origin
        xyz="0.000441875229320685 -0.000105430027601698 -0.00158675124558322"
        rpy="0 0 0" />
      <mass
        value="0.00098313018365204" />
      <inertia
        ixx="2.72780814792229E-08"
        ixy="1.86463715352538E-11"
        ixz="1.83135757568997E-11"
        iyy="4.80453464098759E-08"
        iyz="1.81575171892111E-12"
        izz="7.48563776021965E-08" />
    </inertial>
    <visual>
      <origin
        xyz="0 0 0"
        rpy="0 0 0" />
      <geometry>
        <mesh
          filename="package://matrix_true_description/meshes/imu_link.STL" />
      </geometry>
      <material
        name="">
        <color
          rgba="0.792156862745098 0.819607843137255 0.933333333333333 1" />
      </material>
    </visual>
    <collision>
      <origin
        xyz="0 0 0"
        rpy="0 0 0" />
      <geometry>
        <mesh
          filename="package://matrix_true_description/meshes/imu_link.STL" />
      </geometry>
    </collision>
  </link>
  <joint
    name="imu_joint"
    type="fixed">
    <origin
      xyz="-0.02 0 0.34712"
      rpy="0 0 0" />
    <parent
      link="base_link" />
    <child
      link="imu_link" />
    <axis
      xyz="0 0 0" />
  </joint>
  <link
    name="lidar_merged_link">
    <inertial>
      <origin
        xyz="-0.00299039260663364 -1.43551673135308E-05 -0.0139839903738128"
        rpy="0 0 0" />
      <mass
        value="0.0479836298060718" />
      <inertia
        ixx="2.50495255084653E-05"
        ixy="5.78025332342214E-09"
        ixz="-1.44587790590452E-08"
        iyy="2.67712556764464E-05"
        iyz="-9.23528839252894E-10"
        izz="4.88989812213001E-05" />
    </inertial>
    <visual>
      <origin
        xyz="0 0 0"
        rpy="0 0 0" />
      <geometry>
        <mesh
          filename="package://matrix_true_description/meshes/lidar_merged_link.STL" />
      </geometry>
      <material
        name="">
        <color
          rgba="0.498039215686275 0.498039215686275 0.498039215686275 1" />
      </material>
    </visual>
    <collision>
      <origin
        xyz="0 0 0"
        rpy="0 0 0" />
      <geometry>
        <mesh
          filename="package://matrix_true_description/meshes/lidar_merged_link.STL" />
      </geometry>
    </collision>
  </link>
  <joint
    name="lidar_merged_joint"
    type="fixed">
    <origin
      xyz="0.155 0 0.29572"
      rpy="0 0 0" />
    <parent
      link="base_link" />
    <child
      link="lidar_merged_link" />
    <axis
      xyz="0 0 0" />
  </joint>
  <link
    name="depth_cam_mount_point_link">
    <inertial>
      <origin
        xyz="0.0015077477139305 0.00140603192236628 0.0124765885193783"
        rpy="0 0 0" />
      <mass
        value="0.0364722860415581" />
      <inertia
        ixx="2.3403025638055E-05"
        ixy="2.10291990990204E-07"
        ixz="1.01539830469578E-08"
        iyy="3.50608918373381E-06"
        iyz="1.72626760018301E-09"
        izz="2.36116328630525E-05" />
    </inertial>
    <visual>
      <origin
        xyz="0 0 0"
        rpy="0 0 0" />
      <geometry>
        <mesh
          filename="package://matrix_true_description/meshes/depth_cam_mount_point_link.STL" />
      </geometry>
      <material
        name="">
        <color
          rgba="0.792156862745098 0.819607843137255 0.933333333333333 1" />
      </material>
    </visual>
    <collision>
      <origin
        xyz="0 0 0"
        rpy="0 0 0" />
      <geometry>
        <mesh
          filename="package://matrix_true_description/meshes/depth_cam_mount_point_link.STL" />
      </geometry>
    </collision>
  </link>
  <joint
    name="depth_cam_mount_point_joint"
    type="fixed">
    <origin
      xyz="0.14565 0 0.48012"
      rpy="0 0 0" />
    <parent
      link="base_link" />
    <child
      link="depth_cam_mount_point_link" />
    <axis
      xyz="0 0 0" />
  </joint>
  <link
    name="ultrasonic_fr_link">
    <inertial>
      <origin
        xyz="-0.0166625075197754 0.000133862660593037 -0.000133374282995646"
        rpy="0 0 0" />
      <mass
        value="0.00277452811002927" />
      <inertia
        ixx="2.74219875868265E-07"
        ixy="-1.39284330313772E-08"
        ixz="-2.11726320077891E-09"
        iyy="7.00788316158809E-08"
        iyz="-1.22938238657881E-11"
        izz="2.59571691855632E-07" />
    </inertial>
    <visual>
      <origin
        xyz="0 0 0"
        rpy="0 0 0" />
      <geometry>
        <mesh
          filename="package://matrix_true_description/meshes/ultrasonic_fr_link.STL" />
      </geometry>
      <material
        name="">
        <color
          rgba="0.792156862745098 0.819607843137255 0.933333333333333 1" />
      </material>
    </visual>
    <collision>
      <origin
        xyz="0 0 0"
        rpy="0 0 0" />
      <geometry>
        <mesh
          filename="package://matrix_true_description/meshes/ultrasonic_fr_link.STL" />
      </geometry>
    </collision>
  </link>
  <joint
    name="ultrasonic_fr_joint"
    type="fixed">
    <origin
      xyz="0.16952 -0.1681 0.23408"
      rpy="0 0.001995 -0.71728" />
    <parent
      link="base_link" />
    <child
      link="ultrasonic_fr_link" />
    <axis
      xyz="0 0 0" />
  </joint>
  <link
    name="ultrasonic_fc_link">
    <inertial>
      <origin
        xyz="-0.0145491121704325 5.62235358884378E-06 -0.000136700758250285"
        rpy="0 0 0" />
      <mass
        value="0.00277452812571776" />
      <inertia
        ixx="2.75230866435744E-07"
        ixy="6.48221356846539E-11"
        ixz="-1.8546424712912E-09"
        iyy="6.91328659652775E-08"
        iyz="-1.29469635871373E-10"
        izz="2.59506667402336E-07" />
    </inertial>
    <visual>
      <origin
        xyz="0 0 0"
        rpy="0 0 0" />
      <geometry>
        <mesh
          filename="package://matrix_true_description/meshes/ultrasonic_fc_link.STL" />
      </geometry>
      <material
        name="">
        <color
          rgba="0.792156862745098 0.819607843137255 0.933333333333333 1" />
      </material>
    </visual>
    <collision>
      <origin
        xyz="0 0 0"
        rpy="0 0 0" />
      <geometry>
        <mesh
          filename="package://matrix_true_description/meshes/ultrasonic_fc_link.STL" />
      </geometry>
    </collision>
  </link>
  <joint
    name="ultrasonic_fc_joint"
    type="fixed">
    <origin
      xyz="0.21264 0 0.23385"
      rpy="0 0.018394 0" />
    <parent
      link="base_link" />
    <child
      link="ultrasonic_fc_link" />
    <axis
      xyz="0 0 0" />
  </joint>
  <link
    name="ultrasonic_fl_link">
    <inertial>
      <origin
        xyz="0 0 0"
        rpy="0 0 0" />
      <mass
        value="0" />
      <inertia
        ixx="0"
        ixy="0"
        ixz="0"
        iyy="0"
        iyz="0"
        izz="0" />
    </inertial>
    <visual>
      <origin
        xyz="0 0 0"
        rpy="0 0 0" />
      <geometry>
        <mesh
          filename="package://matrix_true_description/meshes/ultrasonic_fl_link.STL" />
      </geometry>
      <material
        name="">
        <color
          rgba="1 1 1 1" />
      </material>
    </visual>
    <collision>
      <origin
        xyz="0 0 0"
        rpy="0 0 0" />
      <geometry>
        <mesh
          filename="package://matrix_true_description/meshes/ultrasonic_fl_link.STL" />
      </geometry>
    </collision>
  </link>
  <joint
    name="ultrasonic_fl_joint"
    type="fixed">
    <origin
      xyz="0.169519435902909 0.168093291552763 0.234083315247261"
      rpy="0 0.00170059039625006 0.717087904309002" />
    <parent
      link="base_link" />
    <child
      link="ultrasonic_fl_link" />
    <axis
      xyz="0 0 0" />
  </joint>
</robot>